Seed set to 23984
GPU available: True (cuda), used: True
TPU available: False, using: 0 TPU cores
IPU available: False, using: 0 IPUs
HPU available: False, using: 0 HPUs
The following callbacks returned in `LightningModule.configure_callbacks` will override existing callbacks passed to Trainer: ModelCheckpoint
You are using a CUDA device ('NVIDIA A30') that has Tensor Cores. To properly utilize them, you should set `torch.set_float32_matmul_precision('medium' | 'high')` which will trade-off precision for performance. For more details, read https://pytorch.org/docs/stable/generated/torch.set_float32_matmul_precision.html#torch.set_float32_matmul_precision
/home/kamalan/.cache/pypoetry/virtualenvs/train-STAtZovC-py3.10/lib/python3.10/site-packages/lightning/fabric/loggers/csv_logs.py:198: Experiment logs directory /home/kamalan/dc-demo/results/test-run/lightning_logs/version_11 exists and is not empty. Previous log files in this directory will be deleted when the new ones are saved!
/home/kamalan/dc-demo/results/test-run/lightning_logs/version_11
2024-02-22 12:02:06,278 - DeepClean Dataset - INFO - Inferred data sample rate 4096.0Hz
2024-02-22 12:02:06,278 - DeepClean Dataset - INFO - Setting up data for fit stage
2024-02-22 12:02:06,278 - DeepClean Dataset - INFO - Loading train data
Traceback (most recent call last):
  File "/home/kamalan/deepclean-demo/projects/test/./try_train.py", line 173, in <module>
    main()
  File "/home/kamalan/deepclean-demo/projects/test/./try_train.py", line 167, in main
    tcli.trainer.fit(tcli.model, tcli.datamodule)
  File "/home/kamalan/.cache/pypoetry/virtualenvs/train-STAtZovC-py3.10/lib/python3.10/site-packages/lightning/pytorch/trainer/trainer.py", line 544, in fit
    call._call_and_handle_interrupt(
  File "/home/kamalan/.cache/pypoetry/virtualenvs/train-STAtZovC-py3.10/lib/python3.10/site-packages/lightning/pytorch/trainer/call.py", line 44, in _call_and_handle_interrupt
    return trainer_fn(*args, **kwargs)
  File "/home/kamalan/.cache/pypoetry/virtualenvs/train-STAtZovC-py3.10/lib/python3.10/site-packages/lightning/pytorch/trainer/trainer.py", line 580, in _fit_impl
    self._run(model, ckpt_path=ckpt_path)
  File "/home/kamalan/.cache/pypoetry/virtualenvs/train-STAtZovC-py3.10/lib/python3.10/site-packages/lightning/pytorch/trainer/trainer.py", line 950, in _run
    call._call_setup_hook(self)  # allow user to setup lightning_module in accelerator environment
  File "/home/kamalan/.cache/pypoetry/virtualenvs/train-STAtZovC-py3.10/lib/python3.10/site-packages/lightning/pytorch/trainer/call.py", line 92, in _call_setup_hook
    _call_lightning_datamodule_hook(trainer, "setup", stage=fn)
  File "/home/kamalan/.cache/pypoetry/virtualenvs/train-STAtZovC-py3.10/lib/python3.10/site-packages/lightning/pytorch/trainer/call.py", line 179, in _call_lightning_datamodule_hook
    return fn(*args, **kwargs)
  File "/home/kamalan/deepclean-demo/projects/test/train/data.py", line 161, in setup
    X, y = self.load_timeseries("train")
  File "/home/kamalan/deepclean-demo/projects/test/train/data.py", line 143, in load_timeseries
    X[i] = torch.Tensor(f[channel][idx])
  File "h5py/_objects.pyx", line 54, in h5py._objects.with_phil.wrapper
  File "h5py/_objects.pyx", line 55, in h5py._objects.with_phil.wrapper
  File "/home/kamalan/.cache/pypoetry/virtualenvs/train-STAtZovC-py3.10/lib/python3.10/site-packages/h5py/_hl/group.py", line 357, in __getitem__
    oid = h5o.open(self.id, self._e(name), lapl=self._lapl)
  File "h5py/_objects.pyx", line 54, in h5py._objects.with_phil.wrapper
  File "h5py/_objects.pyx", line 55, in h5py._objects.with_phil.wrapper
  File "h5py/h5o.pyx", line 189, in h5py.h5o.open
KeyError: "Unable to synchronously open object (object 'PEM-VOLT_AS_TABLE_GND_OUT_DQ' doesn't exist)"
Traceback (most recent call last):
  File "/home/kamalan/deepclean-demo/projects/test/run-train.py", line 67, in <module>
    main()
  File "/home/kamalan/deepclean-demo/projects/test/run-train.py", line 63, in main
    stream_command(command)
  File "/home/kamalan/deepclean-demo/projects/test/run-train.py", line 44, in stream_command
    raise RuntimeError(
RuntimeError: Command 'python ./try_train.py --config ./config-test.yaml' failed with return code 1 and stderr:

